2019-03-15 14:27:24,152 [Thread-311:19320] [django.request:228] [log:log_response] [ERROR]- Internal Server Error: /app1/form_val/
Traceback (most recent call last):
  File "C:\Program Files\python36\lib\site-packages\django\template\backends\django.py", line 61, in render
    return self.template.render(context)
  File "C:\Program Files\python36\lib\site-packages\django\template\base.py", line 171, in render
    return self._render(context)
  File "C:\Program Files\python36\lib\site-packages\django\template\base.py", line 163, in _render
    return self.nodelist.render(context)
  File "C:\Program Files\python36\lib\site-packages\django\template\base.py", line 937, in render
    bit = node.render_annotated(context)
  File "C:\Program Files\python36\lib\site-packages\django\template\base.py", line 904, in render_annotated
    return self.render(context)
  File "C:\Program Files\python36\lib\site-packages\django\template\loader_tags.py", line 176, in render
    template = context.template.engine.get_template(template_name)
  File "C:\Program Files\python36\lib\site-packages\django\template\engine.py", line 144, in get_template
    template, origin = self.find_template(template_name)
  File "C:\Program Files\python36\lib\site-packages\django\template\engine.py", line 130, in find_template
    raise TemplateDoesNotExist(name, tried=tried)
django.template.exceptions.TemplateDoesNotExist: common_templates/choose_cinema.html

The above exception was the direct cause of the following exception:

Traceback (most recent call last):
  File "C:\Program Files\python36\lib\site-packages\django\core\handlers\exception.py", line 34, in inner
    response = get_response(request)
  File "C:\Program Files\python36\lib\site-packages\django\core\handlers\base.py", line 126, in _get_response
    response = self.process_exception_by_middleware(e, request)
  File "C:\Program Files\python36\lib\site-packages\django\core\handlers\base.py", line 124, in _get_response
    response = wrapped_callback(request, *callback_args, **callback_kwargs)
  File "C:\Users\Yang\Desktop\test\knows\app1\views.py", line 20, in form_val
    return render(request,"from_validate.html")
  File "C:\Program Files\python36\lib\site-packages\django\shortcuts.py", line 36, in render
    content = loader.render_to_string(template_name, context, request, using=using)
  File "C:\Program Files\python36\lib\site-packages\django\template\loader.py", line 62, in render_to_string
    return template.render(context, request)
  File "C:\Program Files\python36\lib\site-packages\django\template\backends\django.py", line 63, in render
    reraise(exc, self.backend)
  File "C:\Program Files\python36\lib\site-packages\django\template\backends\django.py", line 84, in reraise
    raise new from exc
django.template.exceptions.TemplateDoesNotExist: common_templates/choose_cinema.html
2019-03-15 14:27:24,438 [Thread-311:19320] [django.request:228] [log:log_response] [ERROR]- Internal Server Error: /app1/form_val/
Traceback (most recent call last):
  File "C:\Program Files\python36\lib\site-packages\django\template\backends\django.py", line 61, in render
    return self.template.render(context)
  File "C:\Program Files\python36\lib\site-packages\django\template\base.py", line 171, in render
    return self._render(context)
  File "C:\Program Files\python36\lib\site-packages\django\template\base.py", line 163, in _render
    return self.nodelist.render(context)
  File "C:\Program Files\python36\lib\site-packages\django\template\base.py", line 937, in render
    bit = node.render_annotated(context)
  File "C:\Program Files\python36\lib\site-packages\django\template\base.py", line 904, in render_annotated
    return self.render(context)
  File "C:\Program Files\python36\lib\site-packages\django\template\loader_tags.py", line 176, in render
    template = context.template.engine.get_template(template_name)
  File "C:\Program Files\python36\lib\site-packages\django\template\engine.py", line 144, in get_template
    template, origin = self.find_template(template_name)
  File "C:\Program Files\python36\lib\site-packages\django\template\engine.py", line 130, in find_template
    raise TemplateDoesNotExist(name, tried=tried)
django.template.exceptions.TemplateDoesNotExist: common_templates/choose_cinema.html

The above exception was the direct cause of the following exception:

Traceback (most recent call last):
  File "C:\Program Files\python36\lib\site-packages\django\core\handlers\exception.py", line 34, in inner
    response = get_response(request)
  File "C:\Program Files\python36\lib\site-packages\django\core\handlers\base.py", line 126, in _get_response
    response = self.process_exception_by_middleware(e, request)
  File "C:\Program Files\python36\lib\site-packages\django\core\handlers\base.py", line 124, in _get_response
    response = wrapped_callback(request, *callback_args, **callback_kwargs)
  File "C:\Users\Yang\Desktop\test\knows\app1\views.py", line 20, in form_val
    return render(request,"from_validate.html")
  File "C:\Program Files\python36\lib\site-packages\django\shortcuts.py", line 36, in render
    content = loader.render_to_string(template_name, context, request, using=using)
  File "C:\Program Files\python36\lib\site-packages\django\template\loader.py", line 62, in render_to_string
    return template.render(context, request)
  File "C:\Program Files\python36\lib\site-packages\django\template\backends\django.py", line 63, in render
    reraise(exc, self.backend)
  File "C:\Program Files\python36\lib\site-packages\django\template\backends\django.py", line 84, in reraise
    raise new from exc
django.template.exceptions.TemplateDoesNotExist: common_templates/choose_cinema.html
